Workbook

Sheet Configuration
A1: Account Balance Tracker - Configuration
A3: Starting Balance | B3: 10000
A4: Starting Date | B4: 46023
A6: INCOME SETTINGS
A7: Bi-Weekly Salary | B7: 3000
A8: Annual Salary Increase % | B8: 0.03
A9: Next Salary Increase Date | B9: 46388

Sheet Projection
A1: Account Balance Projection
A2: This sheet projects your account balance based on recurring expenses and income.
A3: Add one-time expenses in the 'Other Expenses' column. Non-monthly expenses appear in their own column.
A5: Month | B5: Date | C5: Income | D5: Xcel Energy | E5: Verizon Wireless | F5: Lawn Mowing | G5: Dog Walking | H5: Non-Monthly | I5: Other Expenses | J5: Total Recurring | K5: Total Expenses | L5: Balance
A6: Starting | B6: =Configuration!B4 | L6: =Configuration!B3
A7: 1 | B7: =DATE(YEAR(B6), MONTH(B6)+1, 1) | C7: =Configuration!B7*2 | D7: 350 | E7: 250 | F7: 160 | G7: 80 | H7: 750 | I7: 0 | J7: =SUM(D7:G7) | K7: =SUM(D7:I7) | L7: =L6+C7-K7
A8: 2 | B8: =DATE(YEAR(B6), MONTH(B6)+2, 1) | C8: =Configuration!B7*2 | D8: 350 | E8: 250 | F8: 160 | G8: 80 | H8: 0 | I8: 0 | J8: =SUM(D8:G8) | K8: =SUM(D8:I8) | L8: =L7+C8-K8
A9: 3 | B9: =DATE(YEAR(B6), MONTH(B6)+3, 1) | C9: =Configuration!B7*2 | D9: 350 | E9: 250 | F9: 160 | G9: 80 | H9: 0 | I9: 0 | J9: =SUM(D9:G9) | K9: =SUM(D9:I9) | L9: =L8+C9-K9
A10: 4 | B10: =DATE(YEAR(B6), MONTH(B6)+4, 1) | C10: =Configuration!B7*2 | D10: 350 | E10: 250 | F10: 160 | G10: 80 | H10: 2550 | I10: 0 | J10: =SUM(D10:G10) | K10: =SUM(D10:I10) | L10: =L9+C10-K10
A11: 5 | B11: =DATE(YEAR(B6), MONTH(B6)+5, 1) | C11: =Configuration!B7*2 | D11: 350 | E11: 250 | F11: 160 | G11: 80 | H11: 0 | I11: 0 | J11: =SUM(D11:G11) | K11: =SUM(D11:I11) | L11: =L10+C11-K11
A12: 6 | B12: =DATE(YEAR(B6), MONTH(B6)+6, 1) | C12: =Configuration!B7*2 | D12: 350 | E12: 250 | F12: 160 | G12: 80 | H12: 0 | I12: 0 | J12: =SUM(D12:G12) | K12: =SUM(D12:I12) | L12: =L11+C12-K12
A13: 7 | B13: =DATE(YEAR(B6), MONTH(B6)+7, 1) | C13: =Configuration!B7*2 | D13: 350 | E13: 250 | F13: 160 | G13: 80 | H13: 750 | I13: 0 | J13: =SUM(D13:G13) | K13: =SUM(D13:I13) | L13: =L12+C13-K13
A14: 8 | B14: =DATE(YEAR(B6), MONTH(B6)+8, 1) | C14: =Configuration!B7*2 | D14: 350 | E14: 250 | F14: 160 | G14: 80 | H14: 0 | I14: 0 | J14: =SUM(D14:G14) | K14: =SUM(D14:I14) | L14: =L13+C14-K14
A15: 9 | B15: =DATE(YEAR(B6), MONTH(B6)+9, 1) | C15: =Configuration!B7*2 | D15: 280 | E15: 250 | F15: 0 | G15: 80 | H15: 0 | I15: 0 | J15: =SUM(D15:G15) | K15: =SUM(D15:I15) | L15: =L14+C15-K15
A16: 10 | B16: =DATE(YEAR(B6), MONTH(B6)+10, 1) | C16: =Configuration!B7*2 | D16: 280 | E16: 250 | F16: 0 | G16: 80 | H16: 150 | I16: 0 | J16: =SUM(D16:G16) | K16: =SUM(D16:I16) | L16: =L15+C16-K16
A17: 11 | B17: =DATE(YEAR(B6), MONTH(B6)+11, 1) | C17: =Configuration!B7*2 | D17: 280 | E17: 250 | F17: 0 | G17: 80 | H17: 0 | I17: 0 | J17: =SUM(D17:G17) | K17: =SUM(D17:I17) | L17: =L16+C17-K17
A18: 12 | B18: =DATE(YEAR(B6), MONTH(B6)+12, 1) | C18: =Configuration!B7*2 | D18: 320 | E18: 250 | F18: 0 | G18: 0 | H18: 0 | I18: 0 | J18: =SUM(D18:G18) | K18: =SUM(D18:I18) | L18: =L17+C18-K18
A19: 13 | B19: =DATE(YEAR(B6), MONTH(B6)+13, 1) | C19: =Configuration!B7*2 | D19: 320 | E19: 250 | F19: 0 | G19: 0 | H19: 750 | I19: 0 | J19: =SUM(D19:G19) | K19: =SUM(D19:I19) | L19: =L18+C19-K19
A20: 14 | B20: =DATE(YEAR(B6), MONTH(B6)+14, 1) | C20: =Configuration!B7*2 | D20: 320 | E20: 250 | F20: 0 | G20: 0 | H20: 0 | I20: 0 | J20: =SUM(D20:G20) | K20: =SUM(D20:I20) | L20: =L19+C20-K20
A21: 15 | B21: =DATE(YEAR(B6), MONTH(B6)+15, 1) | C21: =Configuration!B7*2 | D21: 320 | E21: 250 | F21: 0 | G21: 0 | H21: 0 | I21: 0 | J21: =SUM(D21:G21) | K21: =SUM(D21:I21) | L21: =L20+C21-K21
A22: 16 | B22: =DATE(YEAR(B6), MONTH(B6)+16, 1) | C22: =Configuration!B7*2 | D22: 320 | E22: 250 | F22: 0 | G22: 0 | H22: 2550 | I22: 0 | J22: =SUM(D22:G22) | K22: =SUM(D22:I22) | L22: =L21+C22-K22
A23: 17 | B23: =DATE(YEAR(B6), MONTH(B6)+17, 1) | C23: =Configuration!B7*2 | D23: 320 | E23: 250 | F23: 0 | G23: 0 | H23: 0 | I23: 0 | J23: =SUM(D23:G23) | K23: =SUM(D23:I23) | L23: =L22+C23-K23
A24: 18 | B24: =DATE(YEAR(B6), MONTH(B6)+18, 1) | C24: =Configuration!B7*2 | D24: 320 | E24: 250 | F24: 0 | G24: 0 | H24: 0 | I24: 0 | J24: =SUM(D24:G24) | K24: =SUM(D24:I24) | L24: =L23+C24-K24
A25: 19 | B25: =DATE(YEAR(B6), MONTH(B6)+19, 1) | C25: =Configuration!B7*2 | D25: 320 | E25: 250 | F25: 0 | G25: 0 | H25: 750 | I25: 0 | J25: =SUM(D25:G25) | K25: =SUM(D25:I25) | L25: =L24+C25-K25
A26: 20 | B26: =DATE(YEAR(B6), MONTH(B6)+20, 1) | C26: =Configuration!B7*2 | D26: 320 | E26: 250 | F26: 0 | G26: 0 | H26: 0 | I26: 0 | J26: =SUM(D26:G26) | K26: =SUM(D26:I26) | L26: =L25+C26-K26
A27: 21 | B27: =DATE(YEAR(B6), MONTH(B6)+21, 1) | C27: =Configuration!B7*2 | D27: 320 | E27: 250 | F27: 0 | G27: 0 | H27: 0 | I27: 0 | J27: =SUM(D27:G27) | K27: =SUM(D27:I27) | L27: =L26+C27-K27
A28: 22 | B28: =DATE(YEAR(B6), MONTH(B6)+22, 1) | C28: =Configuration!B7*2 | D28: 320 | E28: 250 | F28: 0 | G28: 0 | H28: 150 | I28: 0 | J28: =SUM(D28:G28) | K28: =SUM(D28:I28) | L28: =L27+C28-K28
A29: 23 | B29: =DATE(YEAR(B6), MONTH(B6)+23, 1) | C29: =Configuration!B7*2 | D29: 320 | E29: 250 | F29: 0 | G29: 0 | H29: 0 | I29: 0 | J29: =SUM(D29:G29) | K29: =SUM(D29:I29) | L29: =L28+C29-K29
A30: 24 | B30: =DATE(YEAR(B6), MONTH(B6)+24, 1) | C30: =Configuration!B7*2 | D30: 320 | E30: 250 | F30: 0 | G30: 0 | H30: 0 | I30: 0 | J30: =SUM(D30:G30) | K30: =SUM(D30:I30) | L30: =L29+C30-K30
A31: 25 | B31: =DATE(YEAR(B6), MONTH(B6)+25, 1) | C31: =Configuration!B7*2 | D31: 320 | E31: 250 | F31: 0 | G31: 0 | H31: 750 | I31: 0 | J31: =SUM(D31:G31) | K31: =SUM(D31:I31) | L31: =L30+C31-K31
A32: 26 | B32: =DATE(YEAR(B6), MONTH(B6)+26, 1) | C32: =Configuration!B7*2 | D32: 320 | E32: 250 | F32: 0 | G32: 0 | H32: 0 | I32: 0 | J32: =SUM(D32:G32) | K32: =SUM(D32:I32) | L32: =L31+C32-K32
A33: 27 | B33: =DATE(YEAR(B6), MONTH(B6)+27, 1) | C33: =Configuration!B7*2 | D33: 320 | E33: 250 | F33: 0 | G33: 0 | H33: 0 | I33: 0 | J33: =SUM(D33:G33) | K33: =SUM(D33:I33) | L33: =L32+C33-K33
A34: 28 | B34: =DATE(YEAR(B6), MONTH(B6)+28, 1) | C34: =Configuration!B7*2 | D34: 320 | E34: 250 | F34: 0 | G34: 0 | H34: 2550 | I34: 0 | J34: =SUM(D34:G34) | K34: =SUM(D34:I34) | L34: =L33+C34-K34
A35: 29 | B35: =DATE(YEAR(B6), MONTH(B6)+29, 1) | C35: =Configuration!B7*2 | D35: 320 | E35: 250 | F35: 0 | G35: 0 | H35: 0 | I35: 0 | J35: =SUM(D35:G35) | K35: =SUM(D35:I35) | L35: =L34+C35-K35
A36: 30 | B36: =DATE(YEAR(B6), MONTH(B6)+30, 1) | C36: =Configuration!B7*2 | D36: 320 | E36: 250 | F36: 0 | G36: 0 | H36: 0 | I36: 0 | J36: =SUM(D36:G36) | K36: =SUM(D36:I36) | L36: =L35+C36-K36
A37: 31 | B37: =DATE(YEAR(B6), MONTH(B6)+31, 1) | C37: =Configuration!B7*2 | D37: 320 | E37: 250 | F37: 0 | G37: 0 | H37: 750 | I37: 0 | J37: =SUM(D37:G37) | K37: =SUM(D37:I37) | L37: =L36+C37-K37
A38: 32 | B38: =DATE(YEAR(B6), MONTH(B6)+32, 1) | C38: =Configuration!B7*2 | D38: 320 | E38: 250 | F38: 0 | G38: 0 | H38: 0 | I38: 0 | J38: =SUM(D38:G38) | K38: =SUM(D38:I38) | L38: =L37+C38-K38
A39: 33 | B39: =DATE(YEAR(B6), MONTH(B6)+33, 1) | C39: =Configuration!B7*2 | D39: 320 | E39: 250 | F39: 0 | G39: 0 | H39: 0 | I39: 0 | J39: =SUM(D39:G39) | K39: =SUM(D39:I39) | L39: =L38+C39-K39
A40: 34 | B40: =DATE(YEAR(B6), MONTH(B6)+34, 1) | C40: =Configuration!B7*2 | D40: 320 | E40: 250 | F40: 0 | G40: 0 | H40: 150 | I40: 0 | J40: =SUM(D40:G40) | K40: =SUM(D40:I40) | L40: =L39+C40-K40
A41: 35 | B41: =DATE(YEAR(B6), MONTH(B6)+35, 1) | C41: =Configuration!B7*2 | D41: 320 | E41: 250 | F41: 0 | G41: 0 | H41: 0 | I41: 0 | J41: =SUM(D41:G41) | K41: =SUM(D41:I41) | L41: =L40+C41-K41
...

Sheet Expense History
A1: Expense Change History
A2: Use this sheet to define your recurring expenses and when they change.
A3: Each row represents a new value for an expense starting on a specific date.
A5: Expense Name | B5: Effective Date | C5: Monthly Amount | D5: Frequency | E5: Notes
A6: Xcel Energy | B6: 46023 | C6: 350 | D6: Monthly | E6: Initial rate
A7: Verizon Wireless | B7: 46023 | C7: 250 | D7: Monthly | E7: Phone bill
A8: Lawn mowing | B8: 46023 | C8: 160 | D8: Monthly | E8: During growing season
A9: Dog walking | B9: 46023 | C9: 80 | D9: Monthly | E9: Regular service
A11: Xcel Energy | B11: 46266 | C11: 280 | D11: Monthly | E11: Summer ends - lower usage
A12: Lawn mowing | B12: 46266 | C12: 0 | D12: Monthly | E12: Summer ends - no more mowing
A14: Xcel Energy | B14: 46357 | C14: 320 | D14: Monthly | E14: Winter heating
A15: Dog walking | B15: 46357 | C15: 0 | D15: Monthly | E15: Winter - no more walking
A17: HOA Fees | B17: 46023 | C17: 150 | D17: Quarterly | E17: Paid every 3 months
A18: Insurance | B18: 46023 | C18: 600 | D18: Semi-Annual | E18: Paid twice per year
A21: Frequency options: Monthly, Quarterly, Semi-Annual, Annual

Sheet Non-Monthly Expenses
A1: Non-Monthly & One-Time Expenses
A2: Track quarterly, semi-annual, annual, and one-time expenses here.
A3: These expenses will be included in your projection at the appropriate times.
A5: Expense Name | B5: Amount | C5: Frequency | D5: First Payment Date | E5: Last Payment Date | F5: Notes
A6: HOA Fees | B6: 150 | C6: Quarterly | D6: 46023 | E6: 47118 | F6: Paid in Jan, Apr, Jul, Oct
A7: Car Insurance | B7: 600 | C7: Semi-Annual | D7: 46023 | E7: 47118 | F7: Paid in Jan and Jul
A8: Property Tax | B8: 2400 | C8: Annual | D8: 46113 | E8: 47118 | F8: Paid once per year in April
A9: Amazon Prime | B9: 139 | C9: Annual | D9: 46082 | E9: 47118 | F9: Annual subscription
A10: Holiday Gifts | B10: 800 | C10: Annual | D10: 46357 | E10: 47118 | F10: December shopping
A11: Car Registration | B11: 180 | C11: Annual | D11: 46174 | E11: 47118 | F11: Renew in June
A13: Frequency Guide:
A14: • Quarterly: Every 3 months (4 times per year)
A15: • Semi-Annual: Every 6 months (2 times per year)
A16: • Annual: Once per year
A17: • One-Time: Single occurrence (enter same date for First and Last Payment Date)
